Workbook
Name MillingRate: Assumptions!$B$4
Name SSRTarget: Assumptions!$B$5

Sheet README
A1: Rice Statistics for Africa - variables and calculations by country and region
A3: Generated 2026-08-01 from the platform data extracted 2026-07-31T20:17:46Z
A4: https://rachidiaboudou-a11y.github.io/Africa-Rice-statistics---CHIDO/
A6: HOW THIS WORKBOOK IS BUILT
A7: The data sheets carry only what FAOSTAT and USDA PSD actually publish. Every derived
A8: quantity - milled production, yield, consumption, PPC, CPC, SSR, IDR - is an Excel
A9: formula referencing those cells. Nothing is a pasted result. Change the milling rate on
A10: the Assumptions sheet and the entire workbook recalculates.
A12: SHEETS
A13: Assumptions Milling rate and conversion factors. The yellow cells are the inputs.
A14: FAOSTAT Country-year observed variables, plus derived indicators as formulas.
A15: USDA_PSD The same for USDA PSD, which publishes on a milled basis throughout.
... A59: 13(1), 29-42, for the applied formulas.

Sheet Assumptions
A1: Assumptions and conversion factors
A3: Parameter | B3: Value | C3: Unit | D3: Note
A4: Milling rate (paddy to milled) | B4: 0.67 | C4: ratio | D4: FAO convention. AfricaRice/CARD publish 0.667; van Oort et al. (2015) use 0.65. CHANGE THIS CELL and every ratio in the workbook recalculates.
A5: Self-sufficiency target | B5: 100 | C5: % | D5: FAO (2001) definition of self-sufficiency.
A6: FAOSTAT trade item | B6: 30 | C6: item code | D6: Item 30, standardized total rice trade (husked + milled + broken). Item 31 excludes broken rice and understates West African imports severely.
A7: Kilograms per tonne | B7: 1000 | C7: kg/t | D7: Unit conversion used in every per-capita calculation.
A9: Cells in yellow with blue text are inputs. Everything else in this workbook is a formula.

Sheet FAOSTAT
A1: ISO3 | B1: Country | C1: Region | D1: Year | E1: Production, paddy (t) | F1: Area harvested (ha) | G1: Imports (t, milled eq.) | H1: Exports (t, milled eq.) | I1: Population (persons, UN WPP via FAOSTAT) | J1: Import value (1000 USD) | K1: Export value (1000 USD) | L1: Yield as FAOSTAT publishes it (kg/ha) | M1: Production, milled (t) | N1: Yield, derived = P/A (kg/ha) | O1: Apparent consumption (t) | P1: PPC (kg/capita) | Q1: CPC (kg/capita) | R1: SSR (%) | S1: IDR (%) | T1: ICR (ratio) | U1: Net trade (t) | V1: Import bill per capita (USD)
A2: BDI | B2: Burundi | C2: Eastern Africa | D2: 1961 | E2: 3000 | F2: 797 | G2: 2000 | H2: 0 | I2: 2835119 | J2: 250 | K2: 0 | L2: 3764.1 | M2: =IFERROR(E2*MillingRate,"") -> 2010 | N2: =IFERROR(E2*1000/F2,"") -> 3764.1154 | O2: =IFERROR(M2+G2-N(H2),"") -> 4010 | P2: =IFERROR(M2*1000/I2,"") -> 0.70896495 | Q2: =IFERROR(O2*1000/I2,"") -> 1.4144027 | R2: =IF(N(O2)<=0,"",M2/O2*100) -> 50.124688 | S2: =IF(N(O2)<=0,"",G2/O2*100) -> 49.875312 | T2: =IFERROR(M2/G2,"") -> 1.005 | U2: =IFERROR(N(H2)-G2,"") -> -2000 | V2: =IFERROR(J2*1000/I2,"") -> 0.08817972
A3: BDI | B3: Burundi | C3: Eastern Africa | D3: 1962 | E3: 2750 | F3: 1100 | G3: 3000 | H3: 0 | I3: 2907943 | J3: 400 | K3: 0 | L3: 2500 | M3: =IFERROR(E3*MillingRate,"") -> 1842.5 | N3: =IFERROR(E3*1000/F3,"") -> 2500 | O3: =IFERROR(M3+G3-N(H3),"") -> 4842.5 | P3: =IFERROR(M3*1000/I3,"") -> 0.63360939 | Q3: =IFERROR(O3*1000/I3,"") -> 1.6652665 | R3: =IF(N(O3)<=0,"",M3/O3*100) -> 38.048529 | S3: =IF(N(O3)<=0,"",G3/O3*100) -> 61.951471 | T3: =IFERROR(M3/G3,"") -> 0.61416667 | U3: =IFERROR(N(H3)-G3,"") -> -3000 | V3: =IFERROR(J3*1000/I3,"") -> 0.13755428
A4: BDI | B4: Burundi | C4: Eastern Africa | D4: 1963 | E4: 2680 | F4: 960 | G4: 1000 | H4: 0 | I4: 2969841 | J4: 140 | K4: 0 | L4: 2791.7 | M4: =IFERROR(E4*MillingRate,"") -> 1795.6 | N4: =IFERROR(E4*1000/F4,"") -> 2791.6667 | O4: =IFERROR(M4+G4-N(H4),"") -> 2795.6 | P4: =IFERROR(M4*1000/I4,"") -> 0.60461149 | Q4: =IFERROR(O4*1000/I4,"") -> 0.94132986 | R4: =IF(N(O4)<=0,"",M4/O4*100) -> 64.229504 | S4: =IF(N(O4)<=0,"",G4/O4*100) -> 35.770496 | T4: =IFERROR(M4/G4,"") -> 1.7956 | U4: =IFERROR(N(H4)-G4,"") -> -1000 | V4: =IFERROR(J4*1000/I4,"") -> 0.047140571
A5: BDI | B5: Burundi | C5: Eastern Africa | D5: 1964 | E5: 2880 | F5: 1200 | G5: 713 | H5: 0 | I5: 3055650 | J5: 100 | K5: 0 | L5: 2400 | M5: =IFERROR(E5*MillingRate,"") -> 1929.6 | N5: =IFERROR(E5*1000/F5,"") -> 2400 | O5: =IFERROR(M5+G5-N(H5),"") -> 2642.6 | P5: =IFERROR(M5*1000/I5,"") -> 0.63148594 | Q5: =IFERROR(O5*1000/I5,"") -> 0.86482418 | R5: =IF(N(O5)<=0,"",M5/O5*100) -> 73.018996 | S5: =IF(N(O5)<=0,"",G5/O5*100) -> 26.981004 | T5: =IFERROR(M5/G5,"") -> 2.7063114 | U5: =IFERROR(N(H5)-G5,"") -> -713 | V5: =IFERROR(J5*1000/I5,"") -> 0.032726261
A6: BDI | B6: Burundi | C6: Eastern Africa | D6: 1965 | E6: 2178 | F6: 1050 | G6: 1232 | H6: 0 | I6: 3141367 | J6: 173 | K6: 0 | L6: 2074.3 | M6: =IFERROR(E6*MillingRate,"") -> 1459.26 | N6: =IFERROR(E6*1000/F6,"") -> 2074.2857 | O6: =IFERROR(M6+G6-N(H6),"") -> 2691.26 | P6: =IFERROR(M6*1000/I6,"") -> 0.46453025 | Q6: =IFERROR(O6*1000/I6,"") -> 0.8567162 | R6: =IF(N(O6)<=0,"",M6/O6*100) -> 54.222186 | S6: =IF(N(O6)<=0,"",G6/O6*100) -> 45.777814 | T6: =IFERROR(M6/G6,"") -> 1.1844643 | U6: =IFERROR(N(H6)-G6,"") -> -1232 | V6: =IFERROR(J6*1000/I6,"") -> 0.055071566
A7: BDI | B7: Burundi | C7: Eastern Africa | D7: 1966 | E7: 1967 | F7: 962 | G7: 850 | H7: 0 | I7: 3217960 | J7: 155 | K7: 0 | L7: 2044.7 | M7: =IFERROR(E7*MillingRate,"") -> 1317.89 | N7: =IFERROR(E7*1000/F7,"") -> 2044.6985 | O7: =IFERROR(M7+G7-N(H7),"") -> 2167.89 | P7: =IFERROR(M7*1000/I7,"") -> 0.40954207 | Q7: =IFERROR(O7*1000/I7,"") -> 0.67368457 | R7: =IF(N(O7)<=0,"",M7/O7*100) -> 60.791369 | S7: =IF(N(O7)<=0,"",G7/O7*100) -> 39.208631 | T7: =IFERROR(M7/G7,"") -> 1.5504588 | U7: =IFERROR(N(H7)-G7,"") -> -850 | V7: =IFERROR(J7*1000/I7,"") -> 0.048167162
A8: BDI | B8: Burundi | C8: Eastern Africa | D8: 1967 | E8: 1400 | F8: 1424 | G8: 140 | H8: 0 | I8: 3300690 | J8: 27 | K8: 0 | L8: 983.1 | M8: =IFERROR(E8*MillingRate,"") -> 938 | N8: =IFERROR(E8*1000/F8,"") -> 983.14607 | O8: =IFERROR(M8+G8-N(H8),"") -> 1078 | P8: =IFERROR(M8*1000/I8,"") -> 0.284183 | Q8: =IFERROR(O8*1000/I8,"") -> 0.32659838 | R8: =IF(N(O8)<=0,"",M8/O8*100) -> 87.012987 | S8: =IF(N(O8)<=0,"",G8/O8*100) -> 12.987013 | T8: =IFERROR(M8/G8,"") -> 6.7 | U8: =IFERROR(N(H8)-G8,"") -> -140 | V8: =IFERROR(J8*1000/I8,"") -> 0.0081801078
A9: BDI | B9: Burundi | C9: Eastern Africa | D9: 1968 | E9: 4600 | F9: 2200 | G9: 1075 | H9: 0 | I9: 3380387 | J9: 166 | K9: 0 | L9: 2090.9 | M9: =IFERROR(E9*MillingRate,"") -> 3082 | N9: =IFERROR(E9*1000/F9,"") -> 2090.9091 | O9: =IFERROR(M9+G9-N(H9),"") -> 4157 | P9: =IFERROR(M9*1000/I9,"") -> 0.91172993 | Q9: =IFERROR(O9*1000/I9,"") -> 1.2297409 | R9: =IF(N(O9)<=0,"",M9/O9*100) -> 74.140005 | S9: =IF(N(O9)<=0,"",G9/O9*100) -> 25.859995 | T9: =IFERROR(M9/G9,"") -> 2.8669767 | U9: =IFERROR(N(H9)-G9,"") -> -1075 | V9: =IFERROR(J9*1000/I9,"") -> 0.049106803
A10: BDI | B10: Burundi | C10: Eastern Africa | D10: 1969 | E10: 3446 | F10: 2069 | G10: 289 | H10: 0 | I10: 3454590 | J10: 55 | K10: 0 | L10: 1665.5 | M10: =IFERROR(E10*MillingRate,"") -> 2308.82 | N10: =IFERROR(E10*1000/F10,"") -> 1665.5389 | O10: =IFERROR(M10+G10-N(H10),"") -> 2597.82 | P10: =IFERROR(M10*1000/I10,"") -> 0.66833401 | Q10: =IFERROR(O10*1000/I10,"") -> 0.75199083 | R10: =IF(N(O10)<=0,"",M10/O10*100) -> 88.875288 | S10: =IF(N(O10)<=0,"",G10/O10*100) -> 11.124712 | T10: =IFERROR(M10/G10,"") -> 7.9889965 | U10: =IFERROR(N(H10)-G10,"") -> -289 | V10: =IFERROR(J10*1000/I10,"") -> 0.015920847
A11: BDI | B11: Burundi | C11: Eastern Africa | D11: 1970 | E11: 5047 | F11: 3510 | G11: 274 | H11: 61 | I11: 3530432 | J11: 45 | K11: 13 | L11: 1437.9 | M11: =IFERROR(E11*MillingRate,"") -> 3381.49 | N11: =IFERROR(E11*1000/F11,"") -> 1437.8917 | O11: =IFERROR(M11+G11-N(H11),"") -> 3594.49 | P11: =IFERROR(M11*1000/I11,"") -> 0.95781196 | Q11: =IFERROR(O11*1000/I11,"") -> 1.0181445 | R11: =IF(N(O11)<=0,"",M11/O11*100) -> 94.074264 | S11: =IF(N(O11)<=0,"",G11/O11*100) -> 7.6227782 | T11: =IFERROR(M11/G11,"") -> 12.341204 | U11: =IFERROR(N(H11)-G11,"") -> -213 | V11: =IFERROR(J11*1000/I11,"") -> 0.012746315
A12: BDI | B12: Burundi | C12: Eastern Africa | D12: 1971 | E12: 4277 | F12: 3113 | G12: 63 | H12: 684 | I12: 3617289 | J12: 16 | K12: 96 | L12: 1373.9 | M12: =IFERROR(E12*MillingRate,"") -> 2865.59 | N12: =IFERROR(E12*1000/F12,"") -> 1373.9158 | O12: =IFERROR(M12+G12-N(H12),"") -> 2244.59 | P12: =IFERROR(M12*1000/I12,"") -> 0.79219272 | Q12: =IFERROR(O12*1000/I12,"") -> 0.62051719 | R12: =IF(N(O12)<=0,"",M12/O12*100) -> 127.66652 | S12: =IF(N(O12)<=0,"",G12/O12*100) -> 2.8067487 | T12: =IFERROR(M12/G12,"") -> 45.485556 | U12: =IFERROR(N(H12)-G12,"") -> 621 | V12: =IFERROR(J12*1000/I12,"") -> 0.004423202
A13: BDI | B13: Burundi | C13: Eastern Africa | D13: 1972 | E13: 4785 | F13: 2223 | G13: 3005 | H13: 0 | I13: 3617128 | J13: 477 | K13: 0 | L13: 2152.5 | M13: =IFERROR(E13*MillingRate,"") -> 3205.95 | N13: =IFERROR(E13*1000/F13,"") -> 2152.4966 | O13: =IFERROR(M13+G13-N(H13),"") -> 6210.95 | P13: =IFERROR(M13*1000/I13,"") -> 0.88632473 | Q13: =IFERROR(O13*1000/I13,"") -> 1.7170943 | R13: =IF(N(O13)<=0,"",M13/O13*100) -> 51.617707 | S13: =IF(N(O13)<=0,"",G13/O13*100) -> 48.382293 | T13: =IFERROR(M13/G13,"") -> 1.0668719 | U13: =IFERROR(N(H13)-G13,"") -> -3005 | V13: =IFERROR(J13*1000/I13,"") -> 0.13187258
... A54: BDI | B54: Burundi | C54: Eastern Africa | D54: 2013 | E54: 41454 | F54: 21670 | G54: 18061.2 | H54: 0 | I54: 10439341 | J54: 14242 | K54: 0 | L54: 1913 | M54: =IFERROR(E54*MillingRate,"") -> 27774.18 | N54: =IFERROR(E54*1000/F54,"") -> 1912.9672 | O54: =IFERROR(M54+G54-N(H54),"") -> 45835.38 | P54: =IFERROR(M54*1000/I54,"") -> 2.66053 | Q54: =IFERROR(O54*1000/I54,"") -> 4.3906392 | R54: =IF(N(O54)<=0,"",M54/O54*100) -> 60.595505 | S54: =IF(N(O54)<=0,"",G54/O54*100) -> 39.404495 | T54: =IFERROR(M54/G54,"") -> 1.5377815 | U54: =IFERROR(N(H54)-G54,"") -> -18061.2 | V54: =IFERROR(J54*1000/I54,"") -> 1.3642624
A55: BDI | B55: Burundi | C55: Eastern Africa | D55: 2014 | E55: 67377 | F55: 23730 | G55: 13683 | I55: 10799785 | J55: 6093 | L55: 2839.3 | M55: =IFERROR(E55*MillingRate,"") -> 45142.59 | N55: =IFERROR(E55*1000/F55,"") -> 2839.3173 | O55: =IFERROR(M55+G55-N(H55),"") -> 58825.59 | P55: =IFERROR(M55*1000/I55,"") -> 4.1799527 | Q55: =IFERROR(O55*1000/I55,"") -> 5.4469223 | R55: =IF(N(O55)<=0,"",M55/O55*100) -> 76.739715 | S55: =IF(N(O55)<=0,"",G55/O55*100) -> 23.260285 | T55: =IFERROR(M55/G55,"") -> 3.2991734 | U55: =IFERROR(N(H55)-G55,"") -> -13683 | V55: =IFERROR(J55*1000/I55,"") -> 0.5641779
A56: BDI | B56: Burundi | C56: Eastern Africa | D56: 2015 | E56: 38674 | F56: 34246 | G56: 9892.37 | H56: 153.1 | I56: 11047580 | J56: 5164 | K56: 12 | L56: 1129.3 | M56: =IFERROR(E56*MillingRate,"") -> 25911.58 | N56: =IFERROR(E56*1000/F56,"") -> 1129.2998 | O56: =IFERROR(M56+G56-N(H56),"") -> 35650.85 | P56: =IFERROR(M56*1000/I56,"") -> 2.345453 | Q56: =IFERROR(O56*1000/I56,"") -> 3.227028 | R56: =IF(N(O56)<=0,"",M56/O56*100) -> 72.681521 | S56: =IF(N(O56)<=0,"",G56/O56*100) -> 27.747922 | T56: =IFERROR(M56/G56,"") -> 2.6193501 | U56: =IFERROR(N(H56)-G56,"") -> -9739.27 | V56: =IFERROR(J56*1000/I56,"") -> 0.46743269
A57: BDI | B57: Burundi | C57: Eastern Africa | D57: 2016 | E57: 146633 | F57: 63751 | G57: 10869.99 | H57: 0.2 | I57: 11239451 | J57: 5886 | K57: 0 | L57: 2300.1 | M57: =IFERROR(E57*MillingRate,"") -> 98244.11 | N57: =IFERROR(E57*1000/F57,"") -> 2300.0894 | O57: =IFERROR(M57+G57-N(H57),"") -> 109113.9 | P57: =IFERROR(M57*1000/I57,"") -> 8.7410061 | Q57: =IFERROR(O57*1000/I57,"") -> 9.7081165 | R57: =IF(N(O57)<=0,"",M57/O57*100) -> 90.038125 | S57: =IF(N(O57)<=0,"",G57/O57*100) -> 9.962058 | T57: =IFERROR(M57/G57,"") -> 9.0381049 | U57: =IFERROR(N(H57)-G57,"") -> -10869.79 | V57: =IFERROR(J57*1000/I57,"") -> 0.52369106
A58: BDI | B58: Burundi | C58: Eastern Africa | D58: 2017 | E58: 88297.9 | F58: 49501 | G58: 24007.09 | I58: 11506762 | J58: 23887 | L58: 1783.8 | M58: =IFERROR(E58*MillingRate,"") -> 59159.593 | N58: =IFERROR(E58*1000/F58,"") -> 1783.7599 | O58: =IFERROR(M58+G58-N(H58),"") -> 83166.683 | P58: =IFERROR(M58*1000/I58,"") -> 5.1412894 | Q58: =IFERROR(O58*1000/I58,"") -> 7.2276356 | R58: =IF(N(O58)<=0,"",M58/O58*100) -> 71.133765 | S58: =IF(N(O58)<=0,"",G58/O58*100) -> 28.866235 | T58: =IFERROR(M58/G58,"") -> 2.4642551 | U58: =IFERROR(N(H58)-G58,"") -> -24007.09 | V58: =IFERROR(J58*1000/I58,"") -> 2.0759098
A59: BDI | B59: Burundi | C59: Eastern Africa | D59: 2018 | E59: 89296.2 | F59: 49813 | G59: 14141.88 | I59: 11859446 | J59: 9526 | L59: 1792.6 | M59: =IFERROR(E59*MillingRate,"") -> 59828.454 | N59: =IFERROR(E59*1000/F59,"") -> 1792.6284 | O59: =IFERROR(M59+G59-N(H59),"") -> 73970.334 | P59: =IFERROR(M59*1000/I59,"") -> 5.0447933 | Q59: =IFERROR(O59*1000/I59,"") -> 6.2372504 | R59: =IF(N(O59)<=0,"",M59/O59*100) -> 80.881687 | S59: =IF(N(O59)<=0,"",G59/O59*100) -> 19.118313 | T59: =IFERROR(M59/G59,"") -> 4.230587 | U59: =IFERROR(N(H59)-G59,"") -> -14141.88 | V59: =IFERROR(J59*1000/I59,"") -> 0.80324157
A60: BDI | B60: Burundi | C60: Eastern Africa | D60: 2019 | E60: 241210.7 | F60: 142761 | G60: 15267.03 | H60: 0.62 | I60: 12255336 | J60: 14682 | K60: 0 | L60: 1689.6 | M60: =IFERROR(E60*MillingRate,"") -> 161611.17 | N60: =IFERROR(E60*1000/F60,"") -> 1689.612 | O60: =IFERROR(M60+G60-N(H60),"") -> 176877.58 | P60: =IFERROR(M60*1000/I60,"") -> 13.187004 | Q60: =IFERROR(O60*1000/I60,"") -> 14.432699 | R60: =IF(N(O60)<=0,"",M60/O60*100) -> 91.36894 | S60: =IF(N(O60)<=0,"",G60/O60*100) -> 8.6314105 | T60: =IFERROR(M60/G60,"") -> 10.585633 | U60: =IFERROR(N(H60)-G60,"") -> -15266.41 | V60: =IFERROR(J60*1000/I60,"") -> 1.1980088
A61: BDI | B61: Burundi | C61: Eastern Africa | D61: 2020 | E61: 150000 | F61: 93042 | G61: 16843.95 | H61: 3 | I61: 12617036 | J61: 8007 | K61: 3 | L61: 1612.2 | M61: =IFERROR(E61*MillingRate,"") -> 100500 | N61: =IFERROR(E61*1000/F61,"") -> 1612.1751 | O61: =IFERROR(M61+G61-N(H61),"") -> 117340.95 | P61: =IFERROR(M61*1000/I61,"") -> 7.9654207 | Q61: =IFERROR(O61*1000/I61,"") -> 9.3001993 | R61: =IF(N(O61)<=0,"",M61/O61*100) -> 85.647849 | S61: =IF(N(O61)<=0,"",G61/O61*100) -> 14.354707 | T61: =IFERROR(M61/G61,"") -> 5.966534 | U61: =IFERROR(N(H61)-G61,"") -> -16840.95 | V61: =IFERROR(J61*1000/I61,"") -> 0.63461815
A62: BDI | B62: Burundi | C62: Eastern Africa | D62: 2021 | E62: 120000 | F62: 73983 | G62: 21937.38 | I62: 12965481 | J62: 10747 | L62: 1622 | M62: =IFERROR(E62*MillingRate,"") -> 80400 | N62: =IFERROR(E62*1000/F62,"") -> 1621.9942 | O62: =IFERROR(M62+G62-N(H62),"") -> 102337.38 | P62: =IFERROR(M62*1000/I62,"") -> 6.2010812 | Q62: =IFERROR(O62*1000/I62,"") -> 7.8930647 | R62: =IF(N(O62)<=0,"",M62/O62*100) -> 78.563669 | S62: =IF(N(O62)<=0,"",G62/O62*100) -> 21.436331 | T62: =IFERROR(M62/G62,"") -> 3.6649773 | U62: =IFERROR(N(H62)-G62,"") -> -21937.38 | V62: =IFERROR(J62*1000/I62,"") -> 0.82889327
A63: BDI | B63: Burundi | C63: Eastern Africa | D63: 2022 | E63: 115000 | F63: 75963 | G63: 17935.59 | H63: 0.6 | I63: 13321097 | J63: 11750 | K63: 0 | L63: 1513.9 | M63: =IFERROR(E63*MillingRate,"") -> 77050 | N63: =IFERROR(E63*1000/F63,"") -> 1513.8949 | O63: =IFERROR(M63+G63-N(H63),"") -> 94984.99 | P63: =IFERROR(M63*1000/I63,"") -> 5.7840582 | Q63: =IFERROR(O63*1000/I63,"") -> 7.130418 | R63: =IF(N(O63)<=0,"",M63/O63*100) -> 81.11808 | S63: =IF(N(O63)<=0,"",G63/O63*100) -> 18.882552 | T63: =IFERROR(M63/G63,"") -> 4.2959278 | U63: =IFERROR(N(H63)-G63,"") -> -17934.99 | V63: =IFERROR(J63*1000/I63,"") -> 0.88205949
A64: BDI | B64: Burundi | C64: Eastern Africa | D64: 2023 | E64: 125000 | F64: 86614 | G64: 14903.47 | H64: 0 | I64: 13689450 | J64: 10588 | K64: 0 | L64: 1443.2 | M64: =IFERROR(E64*MillingRate,"") -> 83750 | N64: =IFERROR(E64*1000/F64,"") -> 1443.1847 | O64: =IFERROR(M64+G64-N(H64),"") -> 98653.47 | P64: =IFERROR(M64*1000/I64,"") -> 6.1178499 | Q64: =IFERROR(O64*1000/I64,"") -> 7.2065328 | R64: =IF(N(O64)<=0,"",M64/O64*100) -> 84.893111 | S64: =IF(N(O64)<=0,"",G64/O64*100) -> 15.106889 | T64: =IFERROR(M64/G64,"") -> 5.6194967 | U64: =IFERROR(N(H64)-G64,"") -> -14903.47 | V64: =IFERROR(J64*1000/I64,"") -> 0.77344232
A65: BDI | B65: Burundi | C65: Eastern Africa | D65: 2024 | E65: 136000 | F65: 99419 | G65: 20907.98 | H65: 205.81 | I65: 14047786 | J65: 18166 | K65: 45 | L65: 1367.9 | M65: =IFERROR(E65*MillingRate,"") -> 91120 | N65: =IFERROR(E65*1000/F65,"") -> 1367.9478 | O65: =IFERROR(M65+G65-N(H65),"") -> 111822.17 | P65: =IFERROR(M65*1000/I65,"") -> 6.4864314 | Q65: =IFERROR(O65*1000/I65,"") -> 7.9601277 | R65: =IF(N(O65)<=0,"",M65/O65*100) -> 81.486525 | S65: =IF(N(O65)<=0,"",G65/O65*100) -> 18.697527 | T65: =IFERROR(M65/G65,"") -> 4.3581446 | U65: =IFERROR(N(H65)-G65,"") -> -20702.17 | V65: =IFERROR(J65*1000/I65,"") -> 1.2931575
A66: COM | B66: Comoros | C66: Eastern Africa | D66: 1961 | E66: 9000 | F66: 8000 | G66: 5892 | I66: 201201 | J66: 786 | L66: 1125 | M66: =IFERROR(E66*MillingRate,"") -> 6030 | N66: =IFERROR(E66*1000/F66,"") -> 1125 | O66: =IFERROR(M66+G66-N(H66),"") -> 11922 | P66: =IFERROR(M66*1000/I66,"") -> 29.97003 | Q66: =IFERROR(O66*1000/I66,"") -> 59.254179 | R66: =IF(N(O66)<=0,"",M66/O66*100) -> 50.578762 | S66: =IF(N(O66)<=0,"",G66/O66*100) -> 49.421238 | T66: =IFERROR(M66/G66,"") -> 1.0234216 | U66: =IFERROR(N(H66)-G66,"") -> -5892 | V66: =IFERROR(J66*1000/I66,"") -> 3.9065412
A67: COM | B67: Comoros | C67: Eastern Africa | D67: 1962 | E67: 9000 | F67: 8000 | G67: 8352 | I67: 204702 | J67: 1111 | L67: 1125 | M67: =IFERROR(E67*MillingRate,"") -> 6030 | N67: =IFERROR(E67*1000/F67,"") -> 1125 | O67: =IFERROR(M67+G67-N(H67),"") -> 14382 | P67: =IFERROR(M67*1000/I67,"") -> 29.457455 | Q67: =IFERROR(O67*1000/I67,"") -> 70.258229 | R67: =IF(N(O67)<=0,"",M67/O67*100) -> 41.927409 | S67: =IF(N(O67)<=0,"",G67/O67*100) -> 58.072591 | T67: =IFERROR(M67/G67,"") -> 0.72198276 | U67: =IFERROR(N(H67)-G67,"") -> -8352 | V67: =IFERROR(J67*1000/I67,"") -> 5.4274018
A68: COM | B68: Comoros | C68: Eastern Africa | D68: 1963 | E68: 10000 | F68: 9100 | G68: 8674 | I68: 208185 | J68: 1169 | L68: 1098.9 | M68: =IFERROR(E68*MillingRate,"") -> 6700 | N68: =IFERROR(E68*1000/F68,"") -> 1098.9011 | O68: =IFERROR(M68+G68-N(H68),"") -> 15374 | P68: =IFERROR(M68*1000/I68,"") -> 32.182914 | Q68: =IFERROR(O68*1000/I68,"") -> 73.84778 | R68: =IF(N(O68)<=0,"",M68/O68*100) -> 43.58007 | S68: =IF(N(O68)<=0,"",G68/O68*100) -> 56.41993 | T68: =IFERROR(M68/G68,"") -> 0.77242333 | U68: =IFERROR(N(H68)-G68,"") -> -8674 | V68: =IFERROR(J68*1000/I68,"") -> 5.615198
A69: COM | B69: Comoros | C69: Eastern Africa | D69: 1964 | E69: 11000 | F69: 9200 | G69: 8278 | I69: 211644 | J69: 1187 | L69: 1195.7 | M69: =IFERROR(E69*MillingRate,"") -> 7370 | N69: =IFERROR(E69*1000/F69,"") -> 1195.6522 | O69: =IFERROR(M69+G69-N(H69),"") -> 15648 | P69: =IFERROR(M69*1000/I69,"") -> 34.822627 | Q69: =IFERROR(O69*1000/I69,"") -> 73.935477 | R69: =IF(N(O69)<=0,"",M69/O69*100) -> 47.098671 | S69: =IF(N(O69)<=0,"",G69/O69*100) -> 52.901329 | T69: =IFERROR(M69/G69,"") -> 0.89031167 | U69: =IFERROR(N(H69)-G69,"") -> -8278 | V69: =IFERROR(J69*1000/I69,"") -> 5.6084746
A70: COM | B70: Comoros | C70: Eastern Africa | D70: 1965 | E70: 12000 | F70: 10900 | G70: 12888 | I70: 214967 | J70: 1725 | L70: 1100.9 | M70: =IFERROR(E70*MillingRate,"") -> 8040 | N70: =IFERROR(E70*1000/F70,"") -> 1100.9174 | O70: =IFERROR(M70+G70-N(H70),"") -> 20928 | P70: =IFERROR(M70*1000/I70,"") -> 37.401089 | Q70: =IFERROR(O70*1000/I70,"") -> 97.354478 | R70: =IF(N(O70)<=0,"",M70/O70*100) -> 38.417431 | S70: =IF(N(O70)<=0,"",G70/O70*100) -> 61.582569 | T70: =IFERROR(M70/G70,"") -> 0.62383613 | U70: =IFERROR(N(H70)-G70,"") -> -12888 | V70: =IFERROR(J70*1000/I70,"") -> 8.0244875
A71: COM | B71: Comoros | C71: Eastern Africa | D71: 1966 | E71: 13000 | F71: 12000 | G71: 9288 | I71: 218663 | J71: 1276 | L71: 1083.3 | M71: =IFERROR(E71*MillingRate,"") -> 8710 | N71: =IFERROR(E71*1000/F71,"") -> 1083.3333 | O71: =IFERROR(M71+G71-N(H71),"") -> 17998 | P71: =IFERROR(M71*1000/I71,"") -> 39.832985 | Q71: =IFERROR(O71*1000/I71,"") -> 82.309307 | R71: =IF(N(O71)<=0,"",M71/O71*100) -> 48.394266 | S71: =IF(N(O71)<=0,"",G71/O71*100) -> 51.605734 | T71: =IFERROR(M71/G71,"") -> 0.93776916 | U71: =IFERROR(N(H71)-G71,"") -> -9288 | V71: =IFERROR(J71*1000/I71,"") -> 5.8354637
A72: COM | B72: Comoros | C72: Eastern Africa | D72: 1967 | E72: 12000 | F72: 10900 | G72: 8463 | I72: 223859 | J72: 1350 | L72: 1100.9 | M72: =IFERROR(E72*MillingRate,"") -> 8040 | N72: =IFERROR(E72*1000/F72,"") -> 1100.9174 | O72: =IFERROR(M72+G72-N(H72),"") -> 16503 | P72: =IFERROR(M72*1000/I72,"") -> 35.915465 | Q72: =IFERROR(O72*1000/I72,"") -> 73.720512 | R72: =IF(N(O72)<=0,"",M72/O72*100) -> 48.718415 | S72: =IF(N(O72)<=0,"",G72/O72*100) -> 51.281585 | T72: =IFERROR(M72/G72,"") -> 0.95001772 | U72: =IFERROR(N(H72)-G72,"") -> -8463 | V72: =IFERROR(J72*1000/I72,"") -> 6.0305818
A73: COM | B73: Comoros | C73: Eastern Africa | D73: 1968 | E73: 11000 | F73: 9000 | G73: 10702 | I73: 230244 | J73: 1682 | L73: 1222.2 | M73: =IFERROR(E73*MillingRate,"") -> 7370 | N73: =IFERROR(E73*1000/F73,"") -> 1222.2222 | O73: =IFERROR(M73+G73-N(H73),"") -> 18072 | P73: =IFERROR(M73*1000/I73,"") -> 32.00952 | Q73: =IFERROR(O73*1000/I73,"") -> 78.490645 | R73: =IF(N(O73)<=0,"",M73/O73*100) -> 40.781319 | S73: =IF(N(O73)<=0,"",G73/O73*100) -> 59.218681 | T73: =IFERROR(M73/G73,"") -> 0.68865633 | U73: =IFERROR(N(H73)-G73,"") -> -10702 | V73: =IFERROR(J73*1000/I73,"") -> 7.3052935
A74: COM | B74: Comoros | C74: Eastern Africa | D74: 1969 | E74: 10000 | F74: 9000 | G74: 10972 | I74: 237001 | J74: 1626 | L74: 1111.1 | M74: =IFERROR(E74*MillingRate,"") -> 6700 | N74: =IFERROR(E74*1000/F74,"") -> 1111.1111 | O74: =IFERROR(M74+G74-N(H74),"") -> 17672 | P74: =IFERROR(M74*1000/I74,"") -> 28.269923 | Q74: =IFERROR(O74*1000/I74,"") -> 74.565086 | R74: =IF(N(O74)<=0,"",M74/O74*100) -> 37.913083 | S74: =IF(N(O74)<=0,"",G74/O74*100) -> 62.086917 | T74: =IFERROR(M74/G74,"") -> 0.61064528 | U74: =IFERROR(N(H74)-G74,"") -> -10972 | V74: =IFERROR(J74*1000/I74,"") -> 6.8607305
A75: COM | B75: Comoros | C75: Eastern Africa | D75: 1970 | E75: 10000 | F75: 9000 | G75: 12461 | I75: 244185 | J75: 1637 | L75: 1111.1 | M75: =IFERROR(E75*MillingRate,"") -> 6700 | N75: =IFERROR(E75*1000/F75,"") -> 1111.1111 | O75: =IFERROR(M75+G75-N(H75),"") -> 19161 | P75: =IFERROR(M75*1000/I75,"") -> 27.438213 | Q75: =IFERROR(O75*1000/I75,"") -> 78.469193 | R75: =IF(N(O75)<=0,"",M75/O75*100) -> 34.96686 | S75: =IF(N(O75)<=0,"",G75/O75*100) -> 65.03314 | T75: =IFERROR(M75/G75,"") -> 0.53767755 | U75: =IFERROR(N(H75)-G75,"") -> -12461 | V75: =IFERROR(J75*1000/I75,"") -> 6.7039335
A76: COM | B76: Comoros | C76: Eastern Africa | D76: 1971 | E76: 8000 | F76: 9000 | G76: 20004 | I76: 251865 | J76: 2295 | L76: 888.9 | M76: =IFERROR(E76*MillingRate,"") -> 5360 | N76: =IFERROR(E76*1000/F76,"") -> 888.88889 | O76: =IFERROR(M76+G76-N(H76),"") -> 25364 | P76: =IFERROR(M76*1000/I76,"") -> 21.281242 | Q76: =IFERROR(O76*1000/I76,"") -> 100.70474 | R76: =IF(N(O76)<=0,"",M76/O76*100) -> 21.132314 | S76: =IF(N(O76)<=0,"",G76/O76*100) -> 78.867686 | T76: =IFERROR(M76/G76,"") -> 0.26794641 | U76: =IFERROR(N(H76)-G76,"") -> -20004 | V76: =IFERROR(J76*1000/I76,"") -> 9.1120243
A77: COM | B77: Comoros | C77: Eastern Africa | D77: 1972 | E77: 9000 | F77: 9100 | G77: 14318 | I77: 260077 | J77: 1808 | L77: 989 | M77: =IFERROR(E77*MillingRate,"") -> 6030 | N77: =IFERROR(E77*1000/F77,"") -> 989.01099 | O77: =IFERROR(M77+G77-N(H77),"") -> 20348 | P77: =IFERROR(M77*1000/I77,"") -> 23.185441 | Q77: =IFERROR(O77*1000/I77,"") -> 78.238368 | R77: =IF(N(O77)<=0,"",M77/O77*100) -> 29.634362 | S77: =IF(N(O77)<=0,"",G77/O77*100) -> 70.365638 | T77: =IFERROR(M77/G77,"") -> 0.42114821 | U77: =IFERROR(N(H77)-G77,"") -> -14318 | V77: =IFERROR(J77*1000/I77,"") -> 6.9517874
... A127: COM | B127: Comoros | C127: Eastern Africa | D127: 2022 | E127: 5 | F127: 17 | G127: 55381.99 | I127: 834188 | J127: 32224 | L127: 300 | M127: =IFERROR(E127*MillingRate,"") -> 3.35 | N127: =IFERROR(E127*1000/F127,"") -> 294.11765 | O127: =IFERROR(M127+G127-N(H127),"") -> 55385.34 | P127: =IFERROR(M127*1000/I127,"") -> 0.0040158813 | Q127: =IFERROR(O127*1000/I127,"") -> 66.394314 | R127: =IF(N(O127)<=0,"",M127/O127*100) -> 0.006048532 | S127: =IF(N(O127)<=0,"",G127/O127*100) -> 99.993951 | T127: =IFERROR(M127/G127,"") -> 6.0488978e-05 | U127: =IFERROR(N(H127)-G127,"") -> -55381.99 | V127: =IFERROR(J127*1000/I127,"") -> 38.629182
A128: COM | B128: Comoros | C128: Eastern Africa | D128: 2023 | E128: 5 | F128: 17 | G128: 55761.39 | H128: 0.05 | I128: 850387 | J128: 39304 | K128: 0 | L128: 300.1 | M128: =IFERROR(E128*MillingRate,"") -> 3.35 | N128: =IFERROR(E128*1000/F128,"") -> 294.11765 | O128: =IFERROR(M128+G128-N(H128),"") -> 55764.69 | P128: =IFERROR(M128*1000/I128,"") -> 0.0039393829 | Q128: =IFERROR(O128*1000/I128,"") -> 65.575661 | R128: =IF(N(O128)<=0,"",M128/O128*100) -> 0.0060073857 | S128: =IF(N(O128)<=0,"",G128/O128*100) -> 99.994082 | T128: =IFERROR(M128/G128,"") -> 6.0077412e-05 | U128: =IFERROR(N(H128)-G128,"") -> -55761.34 | V128: =IFERROR(J128*1000/I128,"") -> 46.218957
A129: COM | B129: Comoros | C129: Eastern Africa | D129: 2024 | E129: 5 | F129: 17 | G129: 51983.2 | H129: 46.95 | I129: 866628 | J129: 34933 | K129: 10 | L129: 300.3 | M129: =IFERROR(E129*MillingRate,"") -> 3.35 | N129: =IFERROR(E129*1000/F129,"") -> 294.11765 | O129: =IFERROR(M129+G129-N(H129),"") -> 51939.6 | P129: =IFERROR(M129*1000/I129,"") -> 0.0038655571 | Q129: =IFERROR(O129*1000/I129,"") -> 59.932982 | R129: =IF(N(O129)<=0,"",M129/O129*100) -> 0.0064497994 | S129: =IF(N(O129)<=0,"",G129/O129*100) -> 100.08394 | T129: =IFERROR(M129/G129,"") -> 6.4443897e-05 | U129: =IFERROR(N(H129)-G129,"") -> -51936.25 | V129: =IFERROR(J129*1000/I129,"") -> 40.309106
...

Sheet USDA_PSD
A1: ISO3 | B1: Country | C1: Region | D1: Market year | E1: Production, milled (t) | F1: Area harvested (ha) | G1: Imports (t) | H1: Exports (t) | I1: Population (persons, UN WPP) | J1: Apparent consumption (t) | K1: PPC (kg/capita) | L1: CPC (kg/capita) | M1: SSR (%) | N1: IDR (%) | O1: Yield, milled (kg/ha)
A2: DJI | B2: Djibouti | C2: Eastern Africa | D2: 1983 | E2: 0 | F2: 0 | G2: 39000 | H2: 0 | I2: 369553 | J2: =IFERROR(E2+G2-N(H2),"") -> 39000 | K2: =IFERROR(E2*1000/I2,"") -> 0 | L2: =IFERROR(J2*1000/I2,"") -> 105.5329 | M2: =IF(N(J2)<=0,"",E2/J2*100) -> 0 | N2: =IF(N(J2)<=0,"",G2/J2*100) -> 100 | O2: =IFERROR(E2*1000/F2,"")
A3: DJI | B3: Djibouti | C3: Eastern Africa | D3: 1984 | E3: 0 | F3: 0 | G3: 50000 | H3: 0 | I3: 384053 | J3: =IFERROR(E3+G3-N(H3),"") -> 50000 | K3: =IFERROR(E3*1000/I3,"") -> 0 | L3: =IFERROR(J3*1000/I3,"") -> 130.19036 | M3: =IF(N(J3)<=0,"",E3/J3*100) -> 0 | N3: =IF(N(J3)<=0,"",G3/J3*100) -> 100 | O3: =IFERROR(E3*1000/F3,"")
A4: DJI | B4: Djibouti | C4: Eastern Africa | D4: 1985 | E4: 0 | F4: 0 | G4: 26000 | H4: 0 | I4: 402687 | J4: =IFERROR(E4+G4-N(H4),"") -> 26000 | K4: =IFERROR(E4*1000/I4,"") -> 0 | L4: =IFERROR(J4*1000/I4,"") -> 64.566276 | M4: =IF(N(J4)<=0,"",E4/J4*100) -> 0 | N4: =IF(N(J4)<=0,"",G4/J4*100) -> 100 | O4: =IFERROR(E4*1000/F4,"")
A5: DJI | B5: Djibouti | C5: Eastern Africa | D5: 1986 | E5: 0 | F5: 0 | G5: 17000 | H5: 0 | I5: 426341 | J5: =IFERROR(E5+G5-N(H5),"") -> 17000 | K5: =IFERROR(E5*1000/I5,"") -> 0 | L5: =IFERROR(J5*1000/I5,"") -> 39.874185 | M5: =IF(N(J5)<=0,"",E5/J5*100) -> 0 | N5: =IF(N(J5)<=0,"",G5/J5*100) -> 100 | O5: =IFERROR(E5*1000/F5,"")
A6: DJI | B6: Djibouti | C6: Eastern Africa | D6: 1987 | E6: 0 | F6: 0 | G6: 21000 | H6: 0 | I6: 454399 | J6: =IFERROR(E6+G6-N(H6),"") -> 21000 | K6: =IFERROR(E6*1000/I6,"") -> 0 | L6: =IFERROR(J6*1000/I6,"") -> 46.21489 | M6: =IF(N(J6)<=0,"",E6/J6*100) -> 0 | N6: =IF(N(J6)<=0,"",G6/J6*100) -> 100 | O6: =IFERROR(E6*1000/F6,"")
A7: DJI | B7: Djibouti | C7: Eastern Africa | D7: 1988 | E7: 0 | F7: 0 | G7: 15000 | H7: 0 | I7: 484523 | J7: =IFERROR(E7+G7-N(H7),"") -> 15000 | K7: =IFERROR(E7*1000/I7,"") -> 0 | L7: =IFERROR(J7*1000/I7,"") -> 30.958283 | M7: =IF(N(J7)<=0,"",E7/J7*100) -> 0 | N7: =IF(N(J7)<=0,"",G7/J7*100) -> 100 | O7: =IFERROR(E7*1000/F7,"")
A8: DJI | B8: Djibouti | C8: Eastern Africa | D8: 1989 | E8: 0 | F8: 0 | G8: 18000 | H8: 0 | I8: 523355 | J8: =IFERROR(E8+G8-N(H8),"") -> 18000 | K8: =IFERROR(E8*1000/I8,"") -> 0 | L8: =IFERROR(J8*1000/I8,"") -> 34.393481 | M8: =IF(N(J8)<=0,"",E8/J8*100) -> 0 | N8: =IF(N(J8)<=0,"",G8/J8*100) -> 100 | O8: =IFERROR(E8*1000/F8,"")
A9: DJI | B9: Djibouti | C9: Eastern Africa | D9: 1990 | E9: 0 | F9: 0 | G9: 46000 | H9: 0 | I9: 579538 | J9: =IFERROR(E9+G9-N(H9),"") -> 46000 | K9: =IFERROR(E9*1000/I9,"") -> 0 | L9: =IFERROR(J9*1000/I9,"") -> 79.37357 | M9: =IF(N(J9)<=0,"",E9/J9*100) -> 0 | N9: =IF(N(J9)<=0,"",G9/J9*100) -> 100 | O9: =IFERROR(E9*1000/F9,"")
A10: DJI | B10: Djibouti | C10: Eastern Africa | D10: 1991 | E10: 0 | F10: 0 | G10: 60000 | H10: 0 | I10: 631092 | J10: =IFERROR(E10+G10-N(H10),"") -> 60000 | K10: =IFERROR(E10*1000/I10,"") -> 0 | L10: =IFERROR(J10*1000/I10,"") -> 95.073302 | M10: =IF(N(J10)<=0,"",E10/J10*100) -> 0 | N10: =IF(N(J10)<=0,"",G10/J10*100) -> 100 | O10: =IFERROR(E10*1000/F10,"")
A11: DJI | B11: Djibouti | C11: Eastern Africa | D11: 1992 | E11: 0 | F11: 0 | G11: 61000 | H11: 0 | I11: 626010 | J11: =IFERROR(E11+G11-N(H11),"") -> 61000 | K11: =IFERROR(E11*1000/I11,"") -> 0 | L11: =IFERROR(J11*1000/I11,"") -> 97.442533 | M11: =IF(N(J11)<=0,"",E11/J11*100) -> 0 | N11: =IF(N(J11)<=0,"",G11/J11*100) -> 100 | O11: =IFERROR(E11*1000/F11,"")
A12: DJI | B12: Djibouti | C12: Eastern Africa | D12: 1993 | E12: 0 | F12: 0 | G12: 51000 | H12: 0 | I12: 614245 | J12: =IFERROR(E12+G12-N(H12),"") -> 51000 | K12: =IFERROR(E12*1000/I12,"") -> 0 | L12: =IFERROR(J12*1000/I12,"") -> 83.028759 | M12: =IF(N(J12)<=0,"",E12/J12*100) -> 0 | N12: =IF(N(J12)<=0,"",G12/J12*100) -> 100 | O12: =IFERROR(E12*1000/F12,"")
A13: DJI | B13: Djibouti | C13: Eastern Africa | D13: 1994 | E13: 0 | F13: 0 | G13: 19000 | H13: 0 | I13: 626710 | J13: =IFERROR(E13+G13-N(H13),"") -> 19000 | K13: =IFERROR(E13*1000/I13,"") -> 0 | L13: =IFERROR(J13*1000/I13,"") -> 30.317053 | M13: =IF(N(J13)<=0,"",E13/J13*100) -> 0 | N13: =IF(N(J13)<=0,"",G13/J13*100) -> 100 | O13: =IFERROR(E13*1000/F13,"")
... A1251: MAR | B1251: Morocco | C1251: Northern Africa | D1251: 2026 | E1251: 55000 | F1251: 9000 | G1251: 160000 | H1251: 0 | I1251: 38762441 | J1251: =IFERROR(E1251+G1251-N(H1251),"") -> 215000 | K1251: =IFERROR(E1251*1000/I1251,"") -> 1.4188993 | L1251: =IFERROR(J1251*1000/I1251,"") -> 5.5466063 | M1251: =IF(N(J1251)<=0,"",E1251/J1251*100) -> 25.581395 | N1251: =IF(N(J1251)<=0,"",G1251/J1251*100) -> 74.418605 | O1251: =IFERROR(E1251*1000/F1251,"") -> 6111.1111
A1252: SDN | B1252: Sudan | C1252: Northern Africa | D1252: 1960 | E1252: 1000 | F1252: 1000 | G1252: 4000 | H1252: 0 | J1252: =IFERROR(E1252+G1252-N(H1252),"") -> 5000 | K1252: =IFERROR(E1252*1000/I1252,"") | L1252: =IFERROR(J1252*1000/I1252,"") | M1252: =IF(N(J1252)<=0,"",E1252/J1252*100) -> 20 | N1252: =IF(N(J1252)<=0,"",G1252/J1252*100) -> 80 | O1252: =IFERROR(E1252*1000/F1252,"") -> 1000
A1253: SDN | B1253: Sudan | C1253: Northern Africa | D1253: 1961 | E1253: 1000 | F1253: 1000 | G1253: 4000 | H1253: 0 | J1253: =IFERROR(E1253+G1253-N(H1253),"") -> 5000 | K1253: =IFERROR(E1253*1000/I1253,"") | L1253: =IFERROR(J1253*1000/I1253,"") | M1253: =IF(N(J1253)<=0,"",E1253/J1253*100) -> 20 | N1253: =IF(N(J1253)<=0,"",G1253/J1253*100) -> 80 | O1253: =IFERROR(E1253*1000/F1253,"") -> 1000
A1254: SDN | B1254: Sudan | C1254: Northern Africa | D1254: 1962 | E1254: 1000 | F1254: 1000 | G1254: 5000 | H1254: 0 | J1254: =IFERROR(E1254+G1254-N(H1254),"") -> 6000 | K1254: =IFERROR(E1254*1000/I1254,"") | L1254: =IFERROR(J1254*1000/I1254,"") | M1254: =IF(N(J1254)<=0,"",E1254/J1254*100) -> 16.666667 | N1254: =IF(N(J1254)<=0,"",G1254/J1254*100) -> 83.333333 | O1254: =IFERROR(E1254*1000/F1254,"") -> 1000
A1255: SDN | B1255: Sudan | C1255: Northern Africa | D1255: 1963 | E1255: 1000 | F1255: 1000 | G1255: 6000 | H1255: 0 | J1255: =IFERROR(E1255+G1255-N(H1255),"") -> 7000 | K1255: =IFERROR(E1255*1000/I1255,"") | L1255: =IFERROR(J1255*1000/I1255,"") | M1255: =IF(N(J1255)<=0,"",E1255/J1255*100) -> 14.285714 | N1255: =IF(N(J1255)<=0,"",G1255/J1255*100) -> 85.714286 | O1255: =IFERROR(E1255*1000/F1255,"") -> 1000
A1256: SDN | B1256: Sudan | C1256: Northern Africa | D1256: 1964 | E1256: 1000 | F1256: 1000 | G1256: 4000 | H1256: 0 | J1256: =IFERROR(E1256+G1256-N(H1256),"") -> 5000 | K1256: =IFERROR(E1256*1000/I1256,"") | L1256: =IFERROR(J1256*1000/I1256,"") | M1256: =IF(N(J1256)<=0,"",E1256/J1256*100) -> 20 | N1256: =IF(N(J1256)<=0,"",G1256/J1256*100) -> 80 | O1256: =IFERROR(E1256*1000/F1256,"") -> 1000
A1257: SDN | B1257: Sudan | C1257: Northern Africa | D1257: 1965 | E1257: 1000 | F1257: 1000 | G1257: 10000 | H1257: 0 | J1257: =IFERROR(E1257+G1257-N(H1257),"") -> 11000 | K1257: =IFERROR(E1257*1000/I1257,"") | L1257: =IFERROR(J1257*1000/I1257,"") | M1257: =IF(N(J1257)<=0,"",E1257/J1257*100) -> 9.0909091 | N1257: =IF(N(J1257)<=0,"",G1257/J1257*100) -> 90.909091 | O1257: =IFERROR(E1257*1000/F1257,"") -> 1000
A1258: SDN | B1258: Sudan | C1258: Northern Africa | D1258: 1966 | E1258: 0 | F1258: 0 | G1258: 7000 | H1258: 0 | J1258: =IFERROR(E1258+G1258-N(H1258),"") -> 7000 | K1258: =IFERROR(E1258*1000/I1258,"") | L1258: =IFERROR(J1258*1000/I1258,"") | M1258: =IF(N(J1258)<=0,"",E1258/J1258*100) -> 0 | N1258: =IF(N(J1258)<=0,"",G1258/J1258*100) -> 100 | O1258: =IFERROR(E1258*1000/F1258,"")
A1259: SDN | B1259: Sudan | C1259: Northern Africa | D1259: 1967 | E1259: 1000 | F1259: 2000 | G1259: 7000 | H1259: 0 | J1259: =IFERROR(E1259+G1259-N(H1259),"") -> 8000 | K1259: =IFERROR(E1259*1000/I1259,"") | L1259: =IFERROR(J1259*1000/I1259,"") | M1259: =IF(N(J1259)<=0,"",E1259/J1259*100) -> 12.5 | N1259: =IF(N(J1259)<=0,"",G1259/J1259*100) -> 87.5 | O1259: =IFERROR(E1259*1000/F1259,"") -> 500
A1260: SDN | B1260: Sudan | C1260: Northern Africa | D1260: 1968 | E1260: 1000 | F1260: 2000 | G1260: 10000 | H1260: 0 | J1260: =IFERROR(E1260+G1260-N(H1260),"") -> 11000 | K1260: =IFERROR(E1260*1000/I1260,"") | L1260: =IFERROR(J1260*1000/I1260,"") | M1260: =IF(N(J1260)<=0,"",E1260/J1260*100) -> 9.0909091 | N1260: =IF(N(J1260)<=0,"",G1260/J1260*100) -> 90.909091 | O1260: =IFERROR(E1260*1000/F1260,"") -> 500
A1261: SDN | B1261: Sudan | C1261: Northern Africa | D1261: 1969 | E1261: 2000 | F1261: 3000 | G1261: 11000 | H1261: 0 | J1261: =IFERROR(E1261+G1261-N(H1261),"") -> 13000 | K1261: =IFERROR(E1261*1000/I1261,"") | L1261: =IFERROR(J1261*1000/I1261,"") | M1261: =IF(N(J1261)<=0,"",E1261/J1261*100) -> 15.384615 | N1261: =IF(N(J1261)<=0,"",G1261/J1261*100) -> 84.615385 | O1261: =IFERROR(E1261*1000/F1261,"") -> 666.66667
A1262: SDN | B1262: Sudan | C1262: Northern Africa | D1262: 1970 | E1262: 4000 | F1262: 5000 | G1262: 9000 | H1262: 0 | J1262: =IFERROR(E1262+G1262-N(H1262),"") -> 13000 | K1262: =IFERROR(E1262*1000/I1262,"") | L1262: =IFERROR(J1262*1000/I1262,"") | M1262: =IF(N(J1262)<=0,"",E1262/J1262*100) -> 30.769231 | N1262: =IF(N(J1262)<=0,"",G1262/J1262*100) -> 69.230769 | O1262: =IFERROR(E1262*1000/F1262,"") -> 800
A1263: SDN | B1263: Sudan | C1263: Northern Africa | D1263: 1971 | E1263: 5000 | F1263: 5000 | G1263: 9000 | H1263: 0 | J1263: =IFERROR(E1263+G1263-N(H1263),"") -> 14000 | K1263: =IFERROR(E1263*1000/I1263,"") | L1263: =IFERROR(J1263*1000/I1263,"") | M1263: =IF(N(J1263)<=0,"",E1263/J1263*100) -> 35.714286 | N1263: =IF(N(J1263)<=0,"",G1263/J1263*100) -> 64.285714 | O1263: =IFERROR(E1263*1000/F1263,"") -> 1000
... A1303: SDN | B1303: Sudan | C1303: Northern Africa | D1303: 2011 | E1303: 17000 | F1303: 7000 | G1303: 40000 | H1303: 0 | J1303: =IFERROR(E1303+G1303-N(H1303),"") -> 57000 | K1303: =IFERROR(E1303*1000/I1303,"") | L1303: =IFERROR(J1303*1000/I1303,"") | M1303: =IF(N(J1303)<=0,"",E1303/J1303*100) -> 29.824561 | N1303: =IF(N(J1303)<=0,"",G1303/J1303*100) -> 70.175439 | O1303: =IFERROR(E1303*1000/F1303,"") -> 2428.5714
A1304: SDN | B1304: Sudan | C1304: Northern Africa | D1304: 2012 | E1304: 19000 | F1304: 8000 | G1304: 40000 | H1304: 0 | I1304: 36923178 | J1304: =IFERROR(E1304+G1304-N(H1304),"") -> 59000 | K1304: =IFERROR(E1304*1000/I1304,"") -> 0.51458192 | L1304: =IFERROR(J1304*1000/I1304,"") -> 1.5979123 | M1304: =IF(N(J1304)<=0,"",E1304/J1304*100) -> 32.20339 | N1304: =IF(N(J1304)<=0,"",G1304/J1304*100) -> 67.79661 | O1304: =IFERROR(E1304*1000/F1304,"") -> 2375
A1305: SDN | B1305: Sudan | C1305: Northern Africa | D1305: 2013 | E1305: 19000 | F1305: 8000 | G1305: 45000 | H1305: 0 | I1305: 37785849 | J1305: =IFERROR(E1305+G1305-N(H1305),"") -> 64000 | K1305: =IFERROR(E1305*1000/I1305,"") -> 0.50283375 | L1305: =IFERROR(J1305*1000/I1305,"") -> 1.6937558 | M1305: =IF(N(J1305)<=0,"",E1305/J1305*100) -> 29.6875 | N1305: =IF(N(J1305)<=0,"",G1305/J1305*100) -> 70.3125 | O1305: =IFERROR(E1305*1000/F1305,"") -> 2375
A1306: SDN | B1306: Sudan | C1306: Northern Africa | D1306: 2014 | E1306: 0 | F1306: 0 | G1306: 0 | H1306: 0 | I1306: 38823318 | J1306: =IFERROR(E1306+G1306-N(H1306),"") -> 0 | K1306: =IFERROR(E1306*1000/I1306,"") -> 0 | L1306: =IFERROR(J1306*1000/I1306,"") -> 0 | M1306: =IF(N(J1306)<=0,"",E1306/J1306*100) | N1306: =IF(N(J1306)<=0,"",G1306/J1306*100) | O1306: =IFERROR(E1306*1000/F1306,"")
A1307: SDN | B1307: Sudan | C1307: Northern Africa | D1307: 2015 | E1307: 0 | F1307: 0 | G1307: 0 | H1307: 0 | I1307: 40024431 | J1307: =IFERROR(E1307+G1307-N(H1307),"") -> 0 | K1307: =IFERROR(E1307*1000/I1307,"") -> 0 | L1307: =IFERROR(J1307*1000/I1307,"") -> 0 | M1307: =IF(N(J1307)<=0,"",E1307/J1307*100) | N1307: =IF(N(J1307)<=0,"",G1307/J1307*100) | O1307: =IFERROR(E1307*1000/F1307,"")
A1308: SDN | B1308: Sudan | C1308: Northern Africa | D1308: 2016 | E1308: 0 | F1308: 0 | G1308: 0 | H1308: 0 | I1308: 41259892 | J1308: =IFERROR(E1308+G1308-N(H1308),"") -> 0 | K1308: =IFERROR(E1308*1000/I1308,"") -> 0 | L1308: =IFERROR(J1308*1000/I1308,"") -> 0 | M1308: =IF(N(J1308)<=0,"",E1308/J1308*100) | N1308: =IF(N(J1308)<=0,"",G1308/J1308*100) | O1308: =IFERROR(E1308*1000/F1308,"")
A1309: SDN | B1309: Sudan | C1309: Northern Africa | D1309: 2017 | E1309: 0 | F1309: 0 | G1309: 0 | H1309: 0 | I1309: 42714306 | J1309: =IFERROR(E1309+G1309-N(H1309),"") -> 0 | K1309: =IFERROR(E1309*1000/I1309,"") -> 0 | L1309: =IFERROR(J1309*1000/I1309,"") -> 0 | M1309: =IF(N(J1309)<=0,"",E1309/J1309*100) | N1309: =IF(N(J1309)<=0,"",G1309/J1309*100) | O1309: =IFERROR(E1309*1000/F1309,"")
A1310: SDN | B1310: Sudan | C1310: Northern Africa | D1310: 2018 | E1310: 0 | F1310: 0 | G1310: 0 | H1310: 0 | I1310: 44230596 | J1310: =IFERROR(E1310+G1310-N(H1310),"") -> 0 | K1310: =IFERROR(E1310*1000/I1310,"") -> 0 | L1310: =IFERROR(J1310*1000/I1310,"") -> 0 | M1310: =IF(N(J1310)<=0,"",E1310/J1310*100) | N1310: =IF(N(J1310)<=0,"",G1310/J1310*100) | O1310: =IFERROR(E1310*1000/F1310,"")
A1311: SDN | B1311: Sudan | C1311: Northern Africa | D1311: 2019 | E1311: 0 | F1311: 0 | G1311: 0 | H1311: 0 | I1311: 45548176 | J1311: =IFERROR(E1311+G1311-N(H1311),"") -> 0 | K1311: =IFERROR(E1311*1000/I1311,"") -> 0 | L1311: =IFERROR(J1311*1000/I1311,"") -> 0 | M1311: =IF(N(J1311)<=0,"",E1311/J1311*100) | N1311: =IF(N(J1311)<=0,"",G1311/J1311*100) | O1311: =IFERROR(E1311*1000/F1311,"")
A1312: SDN | B1312: Sudan | C1312: Northern Africa | D1312: 2020 | E1312: 0 | F1312: 0 | G1312: 0 | H1312: 0 | I1312: 46789231 | J1312: =IFERROR(E1312+G1312-N(H1312),"") -> 0 | K1312: =IFERROR(E1312*1000/I1312,"") -> 0 | L1312: =IFERROR(J1312*1000/I1312,"") -> 0 | M1312: =IF(N(J1312)<=0,"",E1312/J1312*100) | N1312: =IF(N(J1312)<=0,"",G1312/J1312*100) | O1312: =IFERROR(E1312*1000/F1312,"")
A1313: SDN | B1313: Sudan | C1313: Northern Africa | D1313: 2021 | E1313: 0 | F1313: 0 | G1313: 0 | H1313: 0 | I1313: 48066924 | J1313: =IFERROR(E1313+G1313-N(H1313),"") -> 0 | K1313: =IFERROR(E1313*1000/I1313,"") -> 0 | L1313: =IFERROR(J1313*1000/I1313,"") -> 0 | M1313: =IF(N(J1313)<=0,"",E1313/J1313*100) | N1313: =IF(N(J1313)<=0,"",G1313/J1313*100) | O1313: =IFERROR(E1313*1000/F1313,"")
A1314: SDN | B1314: Sudan | C1314: Northern Africa | D1314: 2022 | E1314: 0 | F1314: 0 | G1314: 0 | H1314: 0 | I1314: 49383346 | J1314: =IFERROR(E1314+G1314-N(H1314),"") -> 0 | K1314: =IFERROR(E1314*1000/I1314,"") -> 0 | L1314: =IFERROR(J1314*1000/I1314,"") -> 0 | M1314: =IF(N(J1314)<=0,"",E1314/J1314*100) | N1314: =IF(N(J1314)<=0,"",G1314/J1314*100) | O1314: =IFERROR(E1314*1000/F1314,"")
A1315: SDN | B1315: Sudan | C1315: Northern Africa | D1315: 2023 | E1315: 0 | F1315: 0 | G1315: 0 | H1315: 0 | I1315: 50042791 | J1315: =IFERROR(E1315+G1315-N(H1315),"") -> 0 | K1315: =IFERROR(E1315*1000/I1315,"") -> 0 | L1315: =IFERROR(J1315*1000/I1315,"") -> 0 | M1315: =IF(N(J1315)<=0,"",E1315/J1315*100) | N1315: =IF(N(J1315)<=0,"",G1315/J1315*100) | O1315: =IFERROR(E1315*1000/F1315,"")
... A2473: TGO | B2473: Togo | C2473: Western Africa | D2473: 2026 | E2473: 120000 | F2473: 105000 | G2473: 325000 | H2473: 0 | I2473: 8780006 | J2473: =IFERROR(E2473+G2473-N(H2473),"") -> 445000 | K2473: =IFERROR(E2473*1000/I2473,"") -> 13.667417 | L2473: =IFERROR(J2473*1000/I2473,"") -> 50.683337 | M2473: =IF(N(J2473)<=0,"",E2473/J2473*100) -> 26.966292 | N2473: =IF(N(J2473)<=0,"",G2473/J2473*100) -> 73.033708 | O2473: =IFERROR(E2473*1000/F2473,"") -> 1142.8571

Sheet FoodBalanceSheet
A1: ISO3 | B1: Country | C1: Region | D1: Year | E1: Production, milled (1000 t) | F1: Imports (1000 t) | G1: Exports (1000 t) | H1: Food use (1000 t) | I1: Food per capita (kg) | J1: Domestic supply (1000 t) | K1: Calories from rice (kcal/cap/day) | L1: Release | M1: SSR, balance-sheet basis (%)
A2: COM | B2: Comoros | C2: Eastern Africa | D2: 2010 | E2: 16.08 | F2: 55.61 | H2: 53.6 | I2: 81.7333 | J2: 56.28 | K2: 751.11 | L2: current | M2: =IF(N(E2)+N(F2)-N(G2)<=0,"",E2/(E2+F2-N(G2))*100) -> 22.429907
A3: COM | B3: Comoros | C3: Eastern Africa | D3: 2011 | E3: 18.09 | F3: 40.87 | H3: 56.28 | I3: 84.0448 | J3: 58.96 | K3: 765.53 | L3: current | M3: =IF(N(E3)+N(F3)-N(G3)<=0,"",E3/(E3+F3-N(G3))*100) -> 30.681818
A4: COM | B4: Comoros | C4: Eastern Africa | D4: 2012 | E4: 18.09 | F4: 71.02 | H4: 60.3 | I4: 88.4132 | J4: 62.98 | K4: 786.31 | L4: current | M4: =IF(N(E4)+N(F4)-N(G4)<=0,"",E4/(E4+F4-N(G4))*100) -> 20.300752
A5: COM | B5: Comoros | C5: Eastern Africa | D5: 2013 | E5: 19.43 | F5: 40.87 | H5: 59.63 | I5: 85.1838 | J5: 62.31 | K5: 782.94 | L5: current | M5: =IF(N(E5)+N(F5)-N(G5)<=0,"",E5/(E5+F5-N(G5))*100) -> 32.222222
A6: COM | B6: Comoros | C6: Eastern Africa | D6: 2014 | E6: 20.1 | F6: 57.62 | H6: 57.62 | I6: 80.7819 | J6: 60.97 | K6: 768.84 | L6: current | M6: =IF(N(E6)+N(F6)-N(G6)<=0,"",E6/(E6+F6-N(G6))*100) -> 25.862069
A7: COM | B7: Comoros | C7: Eastern Africa | D7: 2015 | E7: 20.77 | F7: 51.59 | H7: 64.32 | I7: 88.8755 | J7: 67.67 | K7: 804.19 | L7: current | M7: =IF(N(E7)+N(F7)-N(G7)<=0,"",E7/(E7+F7-N(G7))*100) -> 28.703704
A8: COM | B8: Comoros | C8: Eastern Africa | D8: 2016 | E8: 21.44 | F8: 38.19 | H8: 66.33 | I8: 89.6728 | J8: 69.68 | K8: 811.41 | L8: current | M8: =IF(N(E8)+N(F8)-N(G8)<=0,"",E8/(E8+F8-N(G8))*100) -> 35.955056
A9: COM | B9: Comoros | C9: Eastern Africa | D9: 2017 | E9: 20.77 | F9: 34.17 | G9: 0 | H9: 68.34 | I9: 90.2088 | J9: 71.69 | K9: 816.18 | L9: current | M9: =IF(N(E9)+N(F9)-N(G9)<=0,"",E9/(E9+F9-N(G9))*100) -> 37.804878
A10: COM | B10: Comoros | C10: Eastern Africa | D10: 2018 | E10: 20.77 | F10: 47.57 | G10: 0 | H10: 68.34 | I10: 88.7549 | J10: 71.69 | K10: 803.74 | L10: current | M10: =IF(N(E10)+N(F10)-N(G10)<=0,"",E10/(E10+F10-N(G10))*100) -> 30.392157
A11: COM | B11: Comoros | C11: Eastern Africa | D11: 2019 | E11: 20.77 | F11: 137.35 | H11: 89.11 | I11: 112.9352 | J11: 92.46 | K11: 766.66 | L11: current | M11: =IF(N(E11)+N(F11)-N(G11)<=0,"",E11/(E11+F11-N(G11))*100) -> 13.135593
A12: COM | B12: Comoros | C12: Eastern Africa | D12: 2020 | E12: 0 | F12: 125.29 | H12: 125.29 | I12: 156.4048 | J12: 125.29 | K12: 708.21 | L12: current | M12: =IF(N(E12)+N(F12)-N(G12)<=0,"",E12/(E12+F12-N(G12))*100) -> 0
A13: COM | B13: Comoros | C13: Eastern Africa | D13: 2021 | E13: 0 | F13: 126.63 | H13: 125.29 | I13: 153.229 | J13: 125.29 | K13: 685.4 | L13: current | M13: =IF(N(E13)+N(F13)-N(G13)<=0,"",E13/(E13+F13-N(G13))*100) -> 0
A14: COM | B14: Comoros | C14: Eastern Africa | D14: 2022 | E14: 0 | F14: 99.16 | H14: 119.93 | I14: 143.648 | J14: 119.93 | K14: 645.3 | L14: current | M14: =IF(N(E14)+N(F14)-N(G14)<=0,"",E14/(E14+F14-N(G14))*100) -> 0
A15: COM | B15: Comoros | C15: Eastern Africa | D15: 2023 | E15: 0 | F15: 129.98 | G15: 0 | H15: 129.98 | I15: 153.2156 | J15: 129.98 | K15: 676.37 | L15: current | M15: =IF(N(E15)+N(F15)-N(G15)<=0,"",E15/(E15+F15-N(G15))*100) -> 0
A16: ETH | B16: Ethiopia | C16: Eastern Africa | D16: 1993 | E16: 7 | F16: 14 | G16: 0 | H16: 20 | I16: 0.38 | J16: 20 | K16: 3.64 | L16: historic | M16: =IF(N(E16)+N(F16)-N(G16)<=0,"",E16/(E16+F16-N(G16))*100) -> 33.333333
A17: ETH | B17: Ethiopia | C17: Eastern Africa | D17: 1994 | E17: 7 | F17: 10 | G17: 0 | H17: 17 | I17: 0.31 | J17: 17 | K17: 2.98 | L17: historic | M17: =IF(N(E17)+N(F17)-N(G17)<=0,"",E17/(E17+F17-N(G17))*100) -> 41.176471
A18: ETH | B18: Ethiopia | C18: Eastern Africa | D18: 1995 | E18: 7 | F18: 2 | G18: 0 | H18: 9 | I18: 0.15 | J18: 9 | K18: 1.47 | L18: historic | M18: =IF(N(E18)+N(F18)-N(G18)<=0,"",E18/(E18+F18-N(G18))*100) -> 77.777778
A19: ETH | B19: Ethiopia | C19: Eastern Africa | D19: 1996 | E19: 10 | F19: 3 | G19: 0 | H19: 12 | I19: 0.21 | J19: 13 | K19: 2.02 | L19: historic | M19: =IF(N(E19)+N(F19)-N(G19)<=0,"",E19/(E19+F19-N(G19))*100) -> 76.923077
A20: ETH | B20: Ethiopia | C20: Eastern Africa | D20: 1997 | E20: 8 | F20: 4 | G20: 0 | H20: 12 | I20: 0.19 | J20: 12 | K20: 1.86 | L20: historic | M20: =IF(N(E20)+N(F20)-N(G20)<=0,"",E20/(E20+F20-N(G20))*100) -> 66.666667
A21: ETH | B21: Ethiopia | C21: Eastern Africa | D21: 1998 | E21: 9 | F21: 5 | G21: 0 | H21: 14 | I21: 0.23 | J21: 14 | K21: 2.21 | L21: historic | M21: =IF(N(E21)+N(F21)-N(G21)<=0,"",E21/(E21+F21-N(G21))*100) -> 64.285714
A22: ETH | B22: Ethiopia | C22: Eastern Africa | D22: 1999 | E22: 9 | F22: 9 | G22: 0 | H22: 18 | I22: 0.28 | J22: 18 | K22: 2.81 | L22: historic | M22: =IF(N(E22)+N(F22)-N(G22)<=0,"",E22/(E22+F22-N(G22))*100) -> 50
A23: ETH | B23: Ethiopia | C23: Eastern Africa | D23: 2000 | E23: 10 | F23: 3 | G23: 0 | H23: 13 | I23: 0.2 | J23: 13 | K23: 1.88 | L23: historic | M23: =IF(N(E23)+N(F23)-N(G23)<=0,"",E23/(E23+F23-N(G23))*100) -> 76.923077
A24: ETH | B24: Ethiopia | C24: Eastern Africa | D24: 2001 | E24: 10 | F24: 5 | G24: 0 | H24: 15 | I24: 0.22 | J24: 15 | K24: 2.16 | L24: historic | M24: =IF(N(E24)+N(F24)-N(G24)<=0,"",E24/(E24+F24-N(G24))*100) -> 66.666667
A25: ETH | B25: Ethiopia | C25: Eastern Africa | D25: 2002 | E25: 10 | F25: 12 | G25: 0 | H25: 19 | I25: 0.28 | J25: 19 | K25: 2.69 | L25: historic | M25: =IF(N(E25)+N(F25)-N(G25)<=0,"",E25/(E25+F25-N(G25))*100) -> 45.454545
A26: ETH | B26: Ethiopia | C26: Eastern Africa | D26: 2003 | E26: 9 | F26: 21 | G26: 0 | H26: 29 | I26: 0.41 | J26: 29 | K26: 3.99 | L26: historic | M26: =IF(N(E26)+N(F26)-N(G26)<=0,"",E26/(E26+F26-N(G26))*100) -> 30
... A672: ZWE | B672: Zimbabwe | C672: Eastern Africa | D672: 2019 | E672: 0.67 | F672: 78.39 | G672: 0 | H672: 130.65 | I672: 8.5425 | J672: 135.34 | K672: 81.04 | L672: current | M672: =IF(N(E672)+N(F672)-N(G672)<=0,"",E672/(E672+F672-N(G672))*100) -> 0.84745763
A673: ZWE | B673: Zimbabwe | C673: Eastern Africa | D673: 2020 | E673: 0 | F673: 182.91 | H673: 147.4 | I673: 9.5006 | J673: 152.76 | K673: 90.12 | L673: current | M673: =IF(N(E673)+N(F673)-N(G673)<=0,"",E673/(E673+F673-N(G673))*100) -> 0
A674: ZWE | B674: Zimbabwe | C674: Eastern Africa | D674: 2021 | E674: 2.01 | F674: 201.67 | H674: 166.16 | I674: 10.519 | J674: 173.53 | K674: 100.65 | L674: current | M674: =IF(N(E674)+N(F674)-N(G674)<=0,"",E674/(E674+F674-N(G674))*100) -> 0.98684211
A675: ZWE | B675: Zimbabwe | C675: Eastern Africa | D675: 2022 | E675: 0.67 | F675: 236.51 | H675: 198.99 | I675: 12.395 | J675: 206.36 | K675: 117.54 | L675: current | M675: =IF(N(E675)+N(F675)-N(G675)<=0,"",E675/(E675+F675-N(G675))*100) -> 0.28248588
A676: ZWE | B676: Zimbabwe | C676: Eastern Africa | D676: 2023 | E676: 0 | F676: 257.95 | G676: 0 | H676: 209.04 | I676: 12.797 | J676: 217.75 | K676: 121.37 | L676: current | M676: =IF(N(E676)+N(F676)-N(G676)<=0,"",E676/(E676+F676-N(G676))*100) -> 0
A677: AGO | B677: Angola | C677: Middle Africa | D677: 1961 | E677: 19 | F677: 1 | G677: 3 | H677: 15 | I677: 3.01 | J677: 17 | K677: 31.76 | L677: historic | M677: =IF(N(E677)+N(F677)-N(G677)<=0,"",E677/(E677+F677-N(G677))*100) -> 111.76471
A678: AGO | B678: Angola | C678: Middle Africa | D678: 1962 | E678: 15 | F678: 1 | G678: 2 | H678: 12 | I678: 2.41 | J678: 14 | K678: 25.38 | L678: historic | M678: =IF(N(E678)+N(F678)-N(G678)<=0,"",E678/(E678+F678-N(G678))*100) -> 107.14286
A679: AGO | B679: Angola | C679: Middle Africa | D679: 1963 | E679: 17 | F679: 2 | G679: 1 | H679: 16 | I679: 3.03 | J679: 17 | K679: 31.61 | L679: historic | M679: =IF(N(E679)+N(F679)-N(G679)<=0,"",E679/(E679+F679-N(G679))*100) -> 94.444444
A680: AGO | B680: Angola | C680: Middle Africa | D680: 1964 | E680: 17 | F680: 1 | G680: 2 | H680: 14 | I680: 2.68 | J680: 16 | K680: 28.18 | L680: historic | M680: =IF(N(E680)+N(F680)-N(G680)<=0,"",E680/(E680+F680-N(G680))*100) -> 106.25
A681: AGO | B681: Angola | C681: Middle Africa | D681: 1965 | E681: 21 | F681: 2 | G681: 2 | H681: 20 | I681: 3.69 | J681: 22 | K681: 38.58 | L681: historic | M681: =IF(N(E681)+N(F681)-N(G681)<=0,"",E681/(E681+F681-N(G681))*100) -> 100
A682: AGO | B682: Angola | C682: Middle Africa | D682: 1966 | E682: 20 | F682: 3 | G682: 4 | H682: 18 | I682: 3.18 | J682: 19 | K682: 33.27 | L682: historic | M682: =IF(N(E682)+N(F682)-N(G682)<=0,"",E682/(E682+F682-N(G682))*100) -> 105.26316
A683: AGO | B683: Angola | C683: Middle Africa | D683: 1967 | E683: 22 | F683: 2 | G683: 3 | H683: 19 | I683: 3.41 | J683: 21 | K683: 35.75 | L683: historic | M683: =IF(N(E683)+N(F683)-N(G683)<=0,"",E683/(E683+F683-N(G683))*100) -> 104.7619
A684: AGO | B684: Angola | C684: Middle Africa | D684: 1968 | E684: 10 | F684: 2 | G684: 2 | H684: 9 | I684: 1.51 | J684: 10 | K684: 15.85 | L684: historic | M684: =IF(N(E684)+N(F684)-N(G684)<=0,"",E684/(E684+F684-N(G684))*100) -> 100
A685: AGO | B685: Angola | C685: Middle Africa | D685: 1969 | E685: 11 | F685: 2 | G685: 1 | H685: 10 | I685: 1.66 | J685: 11 | K685: 17.31 | L685: historic | M685: =IF(N(E685)+N(F685)-N(G685)<=0,"",E685/(E685+F685-N(G685))*100) -> 91.666667
...

Sheet Regions
A1: Region | B1: Year | C1: Production, paddy (t) | D1: Area harvested (ha) | E1: Imports (t) | F1: Exports (t) | G1: Population (persons) | H1: Countries reporting | I1: Production, milled (t) | J1: Yield, paddy (kg/ha) | K1: Apparent consumption (t) | L1: PPC (kg/capita) | M1: CPC (kg/capita) | N1: SSR (%) | O1: IDR (%)
A2: Eastern Africa | B2: 1961 | C2: =SUMIFS(FAOSTAT!$E$2:$E$3310,FAOSTAT!$D$2:$D$3310,$B2,FAOSTAT!$C$2:$C$3310,$A2) -> 1684134 | D2: =SUMIFS(FAOSTAT!$F$2:$F$3310,FAOSTAT!$D$2:$D$3310,$B2,FAOSTAT!$C$2:$C$3310,$A2) -> 977927 | E2: =SUMIFS(FAOSTAT!$G$2:$G$3310,FAOSTAT!$D$2:$D$3310,$B2,FAOSTAT!$C$2:$C$3310,$A2) -> 127440.2 | F2: =SUMIFS(FAOSTAT!$H$2:$H$3310,FAOSTAT!$D$2:$D$3310,$B2,FAOSTAT!$C$2:$C$3310,$A2) -> 37160 | G2: =SUMIFS(FAOSTAT!$I$2:$I$3310,FAOSTAT!$D$2:$D$3310,$B2,FAOSTAT!$C$2:$C$3310,$A2) -> 59312243 | H2: =COUNTIFS(FAOSTAT!$D$2:$D$3310,$B2,FAOSTAT!$C$2:$C$3310,$A2,FAOSTAT!$E$2:$E$3310,">0") -> 9 | I2: =IFERROR(C2*MillingRate,"") -> 1128369.8 | J2: =IFERROR(C2*1000/D2,"") -> 1722.1469 | K2: =IFERROR(I2+E2-F2,"") -> 1218650 | L2: =IFERROR(I2*1000/G2,"") -> 19.02423 | M2: =IFERROR(K2*1000/G2,"") -> 20.546348 | N2: =IF(N(K2)<=0,"",I2/K2*100) -> 92.591786 | O2: =IF(N(K2)<=0,"",E2/K2*100) -> 10.45749
A3: Eastern Africa | B3: 1962 | C3: =SUMIFS(FAOSTAT!$E$2:$E$3310,FAOSTAT!$D$2:$D$3310,$B3,FAOSTAT!$C$2:$C$3310,$A3) -> 1777551 | D3: =SUMIFS(FAOSTAT!$F$2:$F$3310,FAOSTAT!$D$2:$D$3310,$B3,FAOSTAT!$C$2:$C$3310,$A3) -> 1025097 | E3: =SUMIFS(FAOSTAT!$G$2:$G$3310,FAOSTAT!$D$2:$D$3310,$B3,FAOSTAT!$C$2:$C$3310,$A3) -> 132772.2 | F3: =SUMIFS(FAOSTAT!$H$2:$H$3310,FAOSTAT!$D$2:$D$3310,$B3,FAOSTAT!$C$2:$C$3310,$A3) -> 61039 | G3: =SUMIFS(FAOSTAT!$I$2:$I$3310,FAOSTAT!$D$2:$D$3310,$B3,FAOSTAT!$C$2:$C$3310,$A3) -> 61009399 | H3: =COUNTIFS(FAOSTAT!$D$2:$D$3310,$B3,FAOSTAT!$C$2:$C$3310,$A3,FAOSTAT!$E$2:$E$3310,">0") -> 9 | I3: =IFERROR(C3*MillingRate,"") -> 1190959.2 | J3: =IFERROR(C3*1000/D3,"") -> 1734.032 | K3: =IFERROR(I3+E3-F3,"") -> 1262692.4 | L3: =IFERROR(I3*1000/G3,"") -> 19.520913 | M3: =IFERROR(K3*1000/G3,"") -> 20.696686 | N3: =IF(N(K3)<=0,"",I3/K3*100) -> 94.319028 | O3: =IF(N(K3)<=0,"",E3/K3*100) -> 10.515008
A4: Eastern Africa | B4: 1963 | C4: =SUMIFS(FAOSTAT!$E$2:$E$3310,FAOSTAT!$D$2:$D$3310,$B4,FAOSTAT!$C$2:$C$3310,$A4) -> 1876473 | D4: =SUMIFS(FAOSTAT!$F$2:$F$3310,FAOSTAT!$D$2:$D$3310,$B4,FAOSTAT!$C$2:$C$3310,$A4) -> 1053213 | E4: =SUMIFS(FAOSTAT!$G$2:$G$3310,FAOSTAT!$D$2:$D$3310,$B4,FAOSTAT!$C$2:$C$3310,$A4) -> 141084.6 | F4: =SUMIFS(FAOSTAT!$H$2:$H$3310,FAOSTAT!$D$2:$D$3310,$B4,FAOSTAT!$C$2:$C$3310,$A4) -> 42285 | G4: =SUMIFS(FAOSTAT!$I$2:$I$3310,FAOSTAT!$D$2:$D$3310,$B4,FAOSTAT!$C$2:$C$3310,$A4) -> 62755367 | H4: =COUNTIFS(FAOSTAT!$D$2:$D$3310,$B4,FAOSTAT!$C$2:$C$3310,$A4,FAOSTAT!$E$2:$E$3310,">0") -> 9 | I4: =IFERROR(C4*MillingRate,"") -> 1257236.9 | J4: =IFERROR(C4*1000/D4,"") -> 1781.6652 | K4: =IFERROR(I4+E4-F4,"") -> 1356036.5 | L4: =IFERROR(I4*1000/G4,"") -> 20.033934 | M4: =IFERROR(K4*1000/G4,"") -> 21.608295 | N4: =IF(N(K4)<=0,"",I4/K4*100) -> 92.71409 | O4: =IF(N(K4)<=0,"",E4/K4*100) -> 10.404189
A5: Eastern Africa | B5: 1964 | C5: =SUMIFS(FAOSTAT!$E$2:$E$3310,FAOSTAT!$D$2:$D$3310,$B5,FAOSTAT!$C$2:$C$3310,$A5) -> 1937103 | D5: =SUMIFS(FAOSTAT!$F$2:$F$3310,FAOSTAT!$D$2:$D$3310,$B5,FAOSTAT!$C$2:$C$3310,$A5) -> 1054357 | E5: =SUMIFS(FAOSTAT!$G$2:$G$3310,FAOSTAT!$D$2:$D$3310,$B5,FAOSTAT!$C$2:$C$3310,$A5) -> 151764.2 | F5: =SUMIFS(FAOSTAT!$H$2:$H$3310,FAOSTAT!$D$2:$D$3310,$B5,FAOSTAT!$C$2:$C$3310,$A5) -> 37651 | G5: =SUMIFS(FAOSTAT!$I$2:$I$3310,FAOSTAT!$D$2:$D$3310,$B5,FAOSTAT!$C$2:$C$3310,$A5) -> 64595942 | H5: =COUNTIFS(FAOSTAT!$D$2:$D$3310,$B5,FAOSTAT!$C$2:$C$3310,$A5,FAOSTAT!$E$2:$E$3310,">0") -> 10 | I5: =IFERROR(C5*MillingRate,"") -> 1297859 | J5: =IFERROR(C5*1000/D5,"") -> 1837.2363 | K5: =IFERROR(I5+E5-F5,"") -> 1411972.2 | L5: =IFERROR(I5*1000/G5,"") -> 20.091959 | M5: =IFERROR(K5*1000/G5,"") -> 21.858528 | N5: =IF(N(K5)<=0,"",I5/K5*100) -> 91.91817 | O5: =IF(N(K5)<=0,"",E5/K5*100) -> 10.748384
A6: Eastern Africa | B6: 1965 | C6: =SUMIFS(FAOSTAT!$E$2:$E$3310,FAOSTAT!$D$2:$D$3310,$B6,FAOSTAT!$C$2:$C$3310,$A6) -> 1796378 | D6: =SUMIFS(FAOSTAT!$F$2:$F$3310,FAOSTAT!$D$2:$D$3310,$B6,FAOSTAT!$C$2:$C$3310,$A6) -> 993422 | E6: =SUMIFS(FAOSTAT!$G$2:$G$3310,FAOSTAT!$D$2:$D$3310,$B6,FAOSTAT!$C$2:$C$3310,$A6) -> 232705.2 | F6: =SUMIFS(FAOSTAT!$H$2:$H$3310,FAOSTAT!$D$2:$D$3310,$B6,FAOSTAT!$C$2:$C$3310,$A6) -> 16092 | G6: =SUMIFS(FAOSTAT!$I$2:$I$3310,FAOSTAT!$D$2:$D$3310,$B6,FAOSTAT!$C$2:$C$3310,$A6) -> 66516402 | H6: =COUNTIFS(FAOSTAT!$D$2:$D$3310,$B6,FAOSTAT!$C$2:$C$3310,$A6,FAOSTAT!$E$2:$E$3310,">0") -> 10 | I6: =IFERROR(C6*MillingRate,"") -> 1203573.3 | J6: =IFERROR(C6*1000/D6,"") -> 1808.2728 | K6: =IFERROR(I6+E6-F6,"") -> 1420186.5 | L6: =IFERROR(I6*1000/G6,"") -> 18.094383 | M6: =IFERROR(K6*1000/G6,"") -> 21.350921 | N6: =IF(N(K6)<=0,"",I6/K6*100) -> 84.747552 | O6: =IF(N(K6)<=0,"",E6/K6*100) -> 16.385539
A7: Eastern Africa | B7: 1966 | C7: =SUMIFS(FAOSTAT!$E$2:$E$3310,FAOSTAT!$D$2:$D$3310,$B7,FAOSTAT!$C$2:$C$3310,$A7) -> 1866257 | D7: =SUMIFS(FAOSTAT!$F$2:$F$3310,FAOSTAT!$D$2:$D$3310,$B7,FAOSTAT!$C$2:$C$3310,$A7) -> 1202052 | E7: =SUMIFS(FAOSTAT!$G$2:$G$3310,FAOSTAT!$D$2:$D$3310,$B7,FAOSTAT!$C$2:$C$3310,$A7) -> 156584.2 | F7: =SUMIFS(FAOSTAT!$H$2:$H$3310,FAOSTAT!$D$2:$D$3310,$B7,FAOSTAT!$C$2:$C$3310,$A7) -> 29471 | G7: =SUMIFS(FAOSTAT!$I$2:$I$3310,FAOSTAT!$D$2:$D$3310,$B7,FAOSTAT!$C$2:$C$3310,$A7) -> 68503013 | H7: =COUNTIFS(FAOSTAT!$D$2:$D$3310,$B7,FAOSTAT!$C$2:$C$3310,$A7,FAOSTAT!$E$2:$E$3310,">0") -> 10 | I7: =IFERROR(C7*MillingRate,"") -> 1250392.2 | J7: =IFERROR(C7*1000/D7,"") -> 1552.5593 | K7: =IFERROR(I7+E7-F7,"") -> 1377505.4 | L7: =IFERROR(I7*1000/G7,"") -> 18.253098 | M7: =IFERROR(K7*1000/G7,"") -> 20.108683 | N7: =IF(N(K7)<=0,"",I7/K7*100) -> 90.772218 | O7: =IF(N(K7)<=0,"",E7/K7*100) -> 11.36723
A8: Eastern Africa | B8: 1967 | C8: =SUMIFS(FAOSTAT!$E$2:$E$3310,FAOSTAT!$D$2:$D$3310,$B8,FAOSTAT!$C$2:$C$3310,$A8) -> 1953461 | D8: =SUMIFS(FAOSTAT!$F$2:$F$3310,FAOSTAT!$D$2:$D$3310,$B8,FAOSTAT!$C$2:$C$3310,$A8) -> 1205214 | E8: =SUMIFS(FAOSTAT!$G$2:$G$3310,FAOSTAT!$D$2:$D$3310,$B8,FAOSTAT!$C$2:$C$3310,$A8) -> 139223.2 | F8: =SUMIFS(FAOSTAT!$H$2:$H$3310,FAOSTAT!$D$2:$D$3310,$B8,FAOSTAT!$C$2:$C$3310,$A8) -> 49990 | G8: =SUMIFS(FAOSTAT!$I$2:$I$3310,FAOSTAT!$D$2:$D$3310,$B8,FAOSTAT!$C$2:$C$3310,$A8) -> 70574335 | H8: =COUNTIFS(FAOSTAT!$D$2:$D$3310,$B8,FAOSTAT!$C$2:$C$3310,$A8,FAOSTAT!$E$2:$E$3310,">0") -> 11 | I8: =IFERROR(C8*MillingRate,"") -> 1308818.9 | J8: =IFERROR(C8*1000/D8,"") -> 1620.8416 | K8: =IFERROR(I8+E8-F8,"") -> 1398052.1 | L8: =IFERROR(I8*1000/G8,"") -> 18.545253 | M8: =IFERROR(K8*1000/G8,"") -> 19.809639 | N8: =IF(N(K8)<=0,"",I8/K8*100) -> 93.617319 | O8: =IF(N(K8)<=0,"",E8/K8*100) -> 9.9583701
A9: Eastern Africa | B9: 1968 | C9: =SUMIFS(FAOSTAT!$E$2:$E$3310,FAOSTAT!$D$2:$D$3310,$B9,FAOSTAT!$C$2:$C$3310,$A9) -> 2029712 | D9: =SUMIFS(FAOSTAT!$F$2:$F$3310,FAOSTAT!$D$2:$D$3310,$B9,FAOSTAT!$C$2:$C$3310,$A9) -> 1244861 | E9: =SUMIFS(FAOSTAT!$G$2:$G$3310,FAOSTAT!$D$2:$D$3310,$B9,FAOSTAT!$C$2:$C$3310,$A9) -> 124501.2 | F9: =SUMIFS(FAOSTAT!$H$2:$H$3310,FAOSTAT!$D$2:$D$3310,$B9,FAOSTAT!$C$2:$C$3310,$A9) -> 77307 | G9: =SUMIFS(FAOSTAT!$I$2:$I$3310,FAOSTAT!$D$2:$D$3310,$B9,FAOSTAT!$C$2:$C$3310,$A9) -> 72736750 | H9: =COUNTIFS(FAOSTAT!$D$2:$D$3310,$B9,FAOSTAT!$C$2:$C$3310,$A9,FAOSTAT!$E$2:$E$3310,">0") -> 12 | I9: =IFERROR(C9*MillingRate,"") -> 1359907 | J9: =IFERROR(C9*1000/D9,"") -> 1630.4728 | K9: =IFERROR(I9+E9-F9,"") -> 1407101.2 | L9: =IFERROR(I9*1000/G9,"") -> 18.696285 | M9: =IFERROR(K9*1000/G9,"") -> 19.345121 | N9: =IF(N(K9)<=0,"",I9/K9*100) -> 96.645998 | O9: =IF(N(K9)<=0,"",E9/K9*100) -> 8.8480627
A10: Eastern Africa | B10: 1969 | C10: =SUMIFS(FAOSTAT!$E$2:$E$3310,FAOSTAT!$D$2:$D$3310,$B10,FAOSTAT!$C$2:$C$3310,$A10) -> 2122987 | D10: =SUMIFS(FAOSTAT!$F$2:$F$3310,FAOSTAT!$D$2:$D$3310,$B10,FAOSTAT!$C$2:$C$3310,$A10) -> 1226155 | E10: =SUMIFS(FAOSTAT!$G$2:$G$3310,FAOSTAT!$D$2:$D$3310,$B10,FAOSTAT!$C$2:$C$3310,$A10) -> 168306.2 | F10: =SUMIFS(FAOSTAT!$H$2:$H$3310,FAOSTAT!$D$2:$D$3310,$B10,FAOSTAT!$C$2:$C$3310,$A10) -> 56819 | G10: =SUMIFS(FAOSTAT!$I$2:$I$3310,FAOSTAT!$D$2:$D$3310,$B10,FAOSTAT!$C$2:$C$3310,$A10) -> 74976238 | H10: =COUNTIFS(FAOSTAT!$D$2:$D$3310,$B10,FAOSTAT!$C$2:$C$3310,$A10,FAOSTAT!$E$2:$E$3310,">0") -> 12 | I10: =IFERROR(C10*MillingRate,"") -> 1422401.3 | J10: =IFERROR(C10*1000/D10,"") -> 1731.4181 | K10: =IFERROR(I10+E10-F10,"") -> 1533888.5 | L10: =IFERROR(I10*1000/G10,"") -> 18.971361 | M10: =IFERROR(K10*1000/G10,"") -> 20.458328 | N10: =IF(N(K10)<=0,"",I10/K10*100) -> 92.731727 | O10: =IF(N(K10)<=0,"",E10/K10*100) -> 10.972519
